Workbook

Sheet README
A1: Section 7, pass 2: verification sheet
A3: Every row is one value from the second, page-referenced reading of the 71 empirical studies (reasons for data, learners and measures; model-selection criterion and data; test methodology cited; evidence beyond classifier scores; explicit or implied selection of settings on evaluation data).
A4: How to use: open the PDF at the page in column G, compare with the quote in column F, then set column I (yellow) to verified, corrected or wrong. Put the corrected value and the page in column K.
A5: Column H shows the independent spot check already done on 20 claims (confirmed / partly). Partly confirmed claims were narrowed in the text.
A6: Sheet citations: OpenAlex counts used for the citation ratios, retrieved 2026-10-18. Sheet summary: counts by status, recalculated from the codes sheet.
A7: Example of a filled row: status = verified, checked_by = Tan, note = "quote matches p. 7".
A8: Generated from the Section 7 coded data; regenerate rather than edit the coded values by hand.

Sheet codes
A1: key | B1: study | C1: year | D1: field | E1: coded value | F1: quote (verbatim, max 30 words) | G1: where in the paper | H1: spot check | I1: status | J1: checked_by | K1: correction / note
A2: OSS-1997 | B2: OSS | C2: 1997 | D2: data: reasons | E2: application_domain, imbalance_level, public_benchmark | F2: experimented with some data files from the UCI repository (Murphy and Aha, 1994) so that other researchers can replicate the experiments and double-check our results. | G2: pdf p. 5, Sec. 4.1 (also pdf p. 2, Sec. 1)
A3: OSS-1997 | B3: OSS | C3: 1997 | D3: data: access | E3: all public=False; source per dataset=True; links=False; modified data released=False | G3: pdf p. 5, Sec. 4.1 and Table 3; pdf p. 7, Acknowledgements
A4: OSS-1997 | B4: OSS | C4: 1997 | D4: learners: reasons | E4: popular | F4: In particular, 1-NN and C4.5 were selected because of their widespread use and well-known performance. | G4: pdf p. 5, Sec. 4.1
A5: OSS-1997 | B5: OSS | C5: 1997 | D5: model selection | E5: selected: not stated | criterion: not stated | data: not stated
A6: OSS-1997 | B6: OSS | C6: 1997 | D6: measures: reasons | E6: accuracy_misleading, cost, other | F6: As pointed out by many authors, the classifier's performance in applications of this kind cannot be expressed in terms of the average accuracy | G6: pdf p. 1, Sec. 1; pdf p. 2, Sec. 2.1
A7: OSS-1997 | B7: OSS | C7: 1997 | D7: tests: methodology cited | E7: none
A8: OSS-1997 | B8: OSS | C8: 1997 | D8: beyond classifier scores | E8: other | Tables 4-7 report the number of training examples kept after each selection step (S, C, T) next to a+, a-, g and acc. Figs. 2-4 are schematic drawings of borderline, noisy and redundant negatives, not plots of data. | G8: pdf p. 6, Tables 4-7; pdf pp. 3-4, Figs. 2-4
A9: SHRINK-1998 | B9: SHRINK | C9: 1998 | D9: data: reasons | E9: application_domain | F9: In this paper we describe an application of machine learning to an important environmental problem: detection of oil spills from radar images of the sea surface. | G9: p. 195, Sec. 1; p. 206, Sec. 6 (images deliberately acquired to contain slicks) | H9: partly
A10: SHRINK-1998 | B10: SHRINK | C10: 1998 | D10: data: access | E10: all public=False; source per dataset=True; links=False; modified data released=False | G10: p. 204, Sec. 6; p. 205, Table 2 | H10: partly
A11: SHRINK-1998 | B11: SHRINK | C11: 1998 | D11: learners: reasons | E11: none stated | H11: partly
A12: SHRINK-1998 | B12: SHRINK | C12: 1998 | D12: model selection | E12: selected: best variant | criterion: G-mean | data: evaluation data | F12: Unfortunately, we had too little oil spill data to hold any out for final system testing in the development phase of the project. | G12: p. 203, Sec. 5 (g-mean as feedback on design decisions); p. 205, Sec. 6 (no held-out data) | H12: partly
A13: SHRINK-1998 | B13: SHRINK | C13: 1998 | D13: measures: reasons | E13: accuracy_misleading, threshold_free, minority_focus, cost | F13: This measure would have to address the clear inadequacy of accuracy, which is unuseable in our problem. To this end, we have mainly used the geometric mean | G13: pp. 201-203, Sec. 5 | H13: partly
A14: SHRINK-1998 | B14: SHRINK | C14: 1998 | D14: tests: methodology cited | E14: none | G14: p. 208, Sec. 7 (t-test on one-sided selection results, Table 3) | H14: partly
A15: SHRINK-1998 | B15: SHRINK | C15: 1998 | D15: beyond classifier scores | E15: none | H15: partly
A16: SHRINK-1998 | B16: SHRINK | C16: 1998 | D16: settings chosen on evaluation data | E16: explicit | F16: Unfortunately, we had too little oil spill data to hold any out for final system testing in the development phase of the project. | G16: p. 203, Sec. 5 (g-mean as feedback on design decisions); p. 205, Sec. 6 (no held-out data) | H16: partly
A17: SMOTE-2002 | B17: SMOTE | C17: 2002 | D17: data: reasons | E17: varied_characteristics | F17: These datasets vary extensively in their size and class proportions, thus offering different domains for SMOTE. | G17: p. 333, Sec. 5.1 (also p. 352, Sec. 7: 'varying degrees of imbalance ... diverse testbed')
A18: SMOTE-2002 | B18: SMOTE | C18: 2002 | D18: data: access | E18: all public=False; source per dataset=True; links=True; modified data released=False | G18: pp. 328-334, Sec. 5.1, footnotes 1, 3, 4; Table 2
A19: SMOTE-2002 | B19: SMOTE | C19: 2002 | D19: learners: reasons | E19: other | F19: These different learning algorithms allowed SMOTE to be compared to some methods that can handle misclassification costs directly. | G19: p. 332, Sec. 5
A20: SMOTE-2002 | B20: SMOTE | C20: 2002 | D20: model selection | E20: selected: sampling rate | criterion: not stated | data: evaluation data | F20: We only show the best results from SMOTE combined with under-sampling and the plain under-sampling curve in the graphs. | G20: p. 335, Sec. 5.2
A21: SMOTE-2002 | B21: SMOTE | C21: 2002 | D21: measures: reasons | E21: accuracy_misleading, threshold_free, standard_in_literature, cost | F21: Area Under the ROC Curve (AUC) is a useful metric for classifier performance as it is independent of the decision criterion selected and prior probabilities. | G21: p. 322, Sec. 1; p. 323, Sec. 2
A22: SMOTE-2002 | B22: SMOTE | C22: 2002 | D22: tests: methodology cited | E22: none
A23: SMOTE-2002 | B23: SMOTE | C23: 2002 | D23: beyond classifier scores | E23: toy_2d_visualization, other | Fig. 3 plots decision regions on a 2-attribute, 10% subset of Mammography for replication vs synthetic over-sampling; Fig. 4 compares C4.5 tree sizes | G23: pp. 327-330, Figs. 3-4, Sec. 4.1-4.2
A24: SMOTE-2002 | B24: SMOTE | C24: 2002 | D24: settings chosen on evaluation data | E24: explicit | F24: We only show the best results from SMOTE combined with under-sampling and the plain under-sampling curve in the graphs. | G24: p. 335, Sec. 5.2
A25: SMOTEBoost-2003 | B25: SMOTEBoost | C25: 2003 | D25: data: reasons | E25: varied_characteristics | F25: Data sets used in our experiments contained different degrees of imbalance and different sizes, thus providing a diverse test bed. | G25: p. 117, Sec. 5 (Conclusions)
A26: SMOTEBoost-2003 | B26: SMOTEBoost | C26: 2003 | D26: data: access | E26: all public=None; source per dataset=True; links=True; modified data released=False | G26: p. 112, Sec. 4 and Table 2; refs [1], [20]-[24] p. 118-119
A27: SMOTEBoost-2003 | B27: SMOTEBoost | C27: 2003 | D27: learners: reasons | E27: none stated
A28: SMOTEBoost-2003 | B28: SMOTEBoost | C28: 2003 | D28: model selection | E28: selected: sampling rate | criterion: F1 | data: evaluation data | F28: Tables 3 to 6 include the precision, recall, and F-value for the various methods at different amounts of SMOTE (best values are given in bold). | G28: p. 115, Sec. 4; Tables 3-6
A29: SMOTEBoost-2003 | B29: SMOTEBoost | C29: 2003 | D29: measures: reasons | E29: accuracy_misleading, minority_focus, standard_in_literature | F29: for domains with imbalanced and/or skewed distributions, classification accuracy is not sufficient as a standard performance measure. | G29: p. 108, Sec. 1
A30: SMOTEBoost-2003 | B30: SMOTEBoost | C30: 2003 | D30: tests: methodology cited | E30: none
A31: SMOTEBoost-2003 | B31: SMOTEBoost | C31: 2003 | D31: beyond classifier scores | E31: none
A32: SMOTEBoost-2003 | B32: SMOTEBoost | C32: 2003 | D32: settings chosen on evaluation data | E32: explicit | F32: Tables 3 to 6 include the precision, recall, and F-value for the various methods at different amounts of SMOTE (best values are given in bold). | G32: p. 115, Sec. 4; Tables 3-6
A33: SMOTE-ENN-Tomek-2004 | B33: Batista et al. | C33: 2004 | D33: data: reasons | E33: varied_characteristics | F33: we have selected thirteen data sets from UCI [3] which have different degrees of imbalance. | G33: p. 24, Sec. 5
A34: SMOTE-ENN-Tomek-2004 | B34: Batista et al. | C34: 2004 | D34: data: access | E34: all public=True; source per dataset=True; links=True; modified data released=False | G34: p. 24, Sec. 5; p. 25, Table 3; p. 29, Ref. [3] (UCI URL)
A35: SMOTE-ENN-Tomek-2004 | B35: Batista et al. | C35: 2004 | D35: learners: reasons | E35: none stated
A36: SMOTE-ENN-Tomek-2004 | B36: Batista et al. | C36: 2004 | D36: model selection | E36: selected: none (fixed settings) | criterion: not applicable | data: not applicable | F36: We decided to add/remove examples until a balanced distribution was reached. | G36: p. 25, Sec. 5
A37: SMOTE-ENN-Tomek-2004 | B37: Batista et al. | C37: 2004 | D37: measures: reasons | E37: accuracy_misleading, threshold_free, cost | F37: Error rate and accuracy are particularly suspicious performance measures when studying the effect of class distribution on learning since they are strongly biased to favor the majority class. | G37: pp. 21-22, Sec. 3
A38: SMOTE-ENN-Tomek-2004 | B38: Batista et al. | C38: 2004 | D38: tests: methodology cited | E38: none | G38: p. 26, Sec. 5 (Hsu's MCB test, 95%); p. 27, Tables 6-7
A39: SMOTE-ENN-Tomek-2004 | B39: Batista et al. | C39: 2004 | D39: beyond classifier scores | E39: other | Tables 8-9 and Figs. 6-7 compare number of induced rules and conditions per rule for original vs Random over-sampling, Smote, Smote+Tomek, Smote+ENN (unpruned C4.5). | G39: p. 26, Sec. 5; p. 28, Tables 8-9, Figs. 6-7
A40: Borderline-SMOTE-2005 | B40: Borderline-SMOTE | C40: 2005 | D40: data: reasons | E40: none stated
...

Sheet citations
A1: key | B1: study | C1: year | D1: OpenAlex ID | E1: DOI | F1: citations | G1: per year | H1: match | I1: eligible for ratios | J1: note
A2: ENN-1972 | B2: Wilson ENN | C2: 1972 | D2: W2107686700 | E2: 10.1109/tsmc.1972.4309137 | F2: 2133 | G2: =IF(F2="","",ROUND(F2/(2026-C2+1),1)) -> 38.8 | H2: exact | I2: no
A3: TomekLinks-1976 | B3: Tomek links | C3: 1976 | D3: W1591261915 | E3: 10.1109/tsmc.1976.4309452 | F3: 1288 | G3: =IF(F3="","",ROUND(F3/(2026-C3+1),1)) -> 25.3 | H3: exact | I3: no | J3: Re-verified 2026-10-18 via batch filter=openalex:...; count unchanged.
A4: AdaBoost-1997 | B4: AdaBoost | C4: 1997 | D4: W1988790447 | E4: 10.1006/jcss.1997.1504 | F4: 20446 | G4: =IF(F4="","",ROUND(F4/(2026-C4+1),1)) -> 681.5 | H4: exact | I4: no | J4: JCSS journal version chosen. Alt is the EuroCOLT 1995 conference version (10.1007/3-540-59119-2_166; title misspelled in OpenAlex). Re-verified by batch filter=openalex call on 2026-10-18: count unchanged.
A5: OSS-1997 | B5: OSS | C5: 1997 | D5: W85350352 | F5: 2562 | G5: =IF(F5="","",ROUND(F5/(2026-C5+1),1)) -> 85.4 | H5: exact | I5: yes | J5: OpenAlex splits this paper over two records (one with a misspelled title); the two counts are added.
A6: SHRINK-1998 | B6: SHRINK | C6: 1998 | D6: W1588282782 | E6: 10.1023/a:1007452223027 | F6: 1243 | G6: =IF(F6="","",ROUND(F6/(2026-C6+1),1)) -> 42.9 | H6: exact | I6: yes | J6: Full-title search was refused (HTTP 429); found with fallback query (short title + Kubat). Re-verified by batch filter=openalex call on 2026-10-18: count unchanged.
A7: SMOTE-2002 | B7: SMOTE | C7: 2002 | D7: W2148143831 | E7: 10.1613/jair.953 | F7: 32518 | G7: =IF(F7="","",ROUND(F7/(2026-C7+1),1)) -> 1300.7 | H7: exact | I7: yes
A8: SMOTEBoost-2003 | B8: SMOTEBoost | C8: 2003 | D8: W1563938718 | E8: 10.1007/978-3-540-39804-2_12 | F8: 1738 | G8: =IF(F8="","",ROUND(F8/(2026-C8+1),1)) -> 72.4 | H8: exact | I8: yes | J8: Re-verified 2026-10-18 via batch filter=openalex:...; count unchanged.
A9: SMOTE-ENN-Tomek-2004 | B9: Batista et al. | C9: 2004 | D9: W1993220166 | E9: 10.1145/1007730.1007735 | F9: 4207 | G9: =IF(F9="","",ROUND(F9/(2026-C9+1),1)) -> 182.9 | H9: exact | I9: yes
A10: Borderline-SMOTE-2005 | B10: Borderline-SMOTE | C10: 2005 | D10: W2132791018 | E10: 10.1007/11538059_91 | F10: 4313 | G10: =IF(F10="","",ROUND(F10/(2026-C10+1),1)) -> 196 | H10: exact | I10: yes | J10: Re-verified by batch filter=openalex call on 2026-10-18: count unchanged.
A11: Cluster-SMOTE-2006 | B11: Cluster-SMOTE | C11: 2006 | D11: W2126996952 | E11: 10.1109/grc.2006.1635905 | F11: 303 | G11: =IF(F11="","",ROUND(F11/(2026-C11+1),1)) -> 14.4 | H11: exact | I11: yes | J11: IEEE GrC 2006 (input venue was null). Re-verified 2026-10-18 via batch filter=openalex:...; count unchanged.
A12: Global-CS-2006 | B12: Global-CS | C12: 2006 | G12: =IF(F12="","",ROUND(F12/(2026-C12+1),1)) | H12: uncertain | I12: no | J12: The AAAI 2006 paper has no OpenAlex record; the only match is the 2010 journal version, which is a separate corpus entry. Excluded from citation analysis.
A13: COG-OS-2007 | B13: COG-OS | C13: 2007 | D13: W2151779862 | E13: 10.1145/1281192.1281279 | F13: 67 | G13: =IF(F13="","",ROUND(F13/(2026-C13+1),1)) -> 3.4 | H13: exact | I13: yes | J13: KDD 2007 version chosen to match venue; alt is the extended journal version (Data Min. Knowl. Discov. 2010, DOI 10.1007/s10618-009-0146-1) with a slightly different title.
A14: ADASYN-2008 | B14: ADASYN | C14: 2008 | D14: W2104933073 | E14: 10.1109/ijcnn.2008.4633969 | F14: 4927 | G14: =IF(F14="","",ROUND(F14/(2026-C14+1),1)) -> 259.3 | H14: exact | I14: yes | J14: Full-title search was refused (HTTP 429) and the shorter fallback search did not surface it; found via filter=title.search:ADASYN, year 2007-2009 (only 1 hit). Re-verified 2026-10-18 via batch filter=openalex:...; count unchanged.
A15: LS-2008 | B15: LS | C15: 2008 | D15: W2117689108 | E15: 10.1109/icdm.2008.87 | F15: 75 | G15: =IF(F15="","",ROUND(F15/(2026-C15+1),1)) -> 3.9 | H15: exact | I15: yes | J15: Full-title search was refused (HTTP 429) and the fallback search (title words + Cieslak) returned no match; found with filter=title.search. Re-verified by batch filter=openalex call on 2026-10-18: count unchanged.
A16: EasyEnsemble-BalanceCascade-2009 | B16: EasyEnsemble | C16: 2009 | D16: W2104167780 | E16: 10.1109/tsmcb.2008.2007853 | F16: 2475 | G16: =IF(F16="","",ROUND(F16/(2026-C16+1),1)) -> 137.5 | H16: exact | I16: yes | J16: OpenAlex year 2008 (online-first) vs input 2009 (print issue). Re-verified 2026-10-18 via batch filter=openalex:...; count unchanged.
A17: SBC-2009 | B17: SBC | C17: 2009 | D17: W2128965734 | E17: 10.1016/j.eswa.2008.06.108 | F17: 732 | G17: =IF(F17="","",ROUND(F17/(2026-C17+1),1)) -> 40.7 | H17: exact | I17: yes | J17: Full-title search was refused (HTTP 429) and the fallback search (title + Yen) returned no match; resolved by DOI lookup (works/doi:...), title matches exactly. OpenAlex year 2008 (online first), print 2009. Re-verified by batch filter=openalex call on 2026-10-18: count unchanged.
A18: Safe-Level-SMOTE-2009 | B18: Safe-Level-SMOTE | C18: 2009 | D18: W1496056137 | E18: 10.1007/978-3-642-01307-2_43 | F18: 1023 | G18: =IF(F18="","",ROUND(F18/(2026-C18+1),1)) -> 56.8 | H18: exact | I18: yes | J18: Found via shortened title query (full-title query returned a fetch error).
A19: Global-CS-2010 | B19: Global-CS | C19: 2010 | D19: W72187777 | E19: 10.1111/j.1467-8640.2010.00358.x | F19: 350 | G19: =IF(F19="","",ROUND(F19/(2026-C19+1),1)) -> 20.6 | H19: exact | I19: yes | J19: Computational Intelligence journal version. The AAAI 2006 conference paper of the same title did not appear in the top 5 and was not looked up separately. Re-verified 2026-10-18 via batch filter=openalex:...; count unchanged.
A20: RAMOBoost-2010 | B20: RAMOBoost | C20: 2010 | D20: W2096235960 | E20: 10.1109/tnn.2010.2066988 | F20: 208 | G20: =IF(F20="","",ROUND(F20/(2026-C20+1),1)) -> 12.2 | H20: exact | I20: yes
A21: RUSBoost-2010 | B21: RUSBoost | C21: 2010 | D21: W2096945460 | E21: 10.1109/tsmca.2009.2029559 | F21: 1867 | G21: =IF(F21="","",ROUND(F21/(2026-C21+1),1)) -> 109.8 | H21: exact | I21: yes | J21: OpenAlex year 2009 (online-first) vs input 2010 (print issue). The 2008 ICPR precursor has a different title and was not looked up. Re-verified 2026-10-18 via batch filter=openalex:...; count unchanged.
A22: SPIDER2-2010 | B22: SPIDER2 | C22: 2010 | D22: W1592804209 | E22: 10.1007/978-3-642-13529-3_18 | F22: 229 | G22: =IF(F22="","",ROUND(F22/(2026-C22+1),1)) -> 13.5 | H22: exact | I22: yes | J22: Re-verified by batch filter=openalex call on 2026-10-18: count unchanged.
A23: DSRBF-2011 | B23: DSRBF | C23: 2011 | D23: W2124710650 | E23: 10.1016/j.patcog.2011.02.019 | F23: 152 | G23: =IF(F23="","",ROUND(F23/(2026-C23+1),1)) -> 9.5 | H23: exact | I23: yes
A24: INOS-2013 | B24: INOS | C24: 2013 | D24: W2015681982 | E24: 10.1109/tkde.2013.37 | F24: 129 | G24: =IF(F24="","",ROUND(F24/(2026-C24+1),1)) -> 9.2 | H24: exact | I24: yes | J24: Re-verified by batch filter=openalex call on 2026-10-18: count unchanged.
A25: OVO-SMOTE-2013 | B25: Fernandez et al. | C25: 2013 | D25: W2164341120 | E25: 10.1016/j.knosys.2013.01.018 | F25: 388 | G25: =IF(F25="","",ROUND(F25/(2026-C25+1),1)) -> 27.7 | H25: exact | I25: yes | J25: Full-title search URL was too long; the shortened search was refused (HTTP 429); resolved by DOI lookup (works/doi:...), title matches exactly. Re-verified by batch filter=openalex call on 2026-10-18: count unchanged.
A26: MWMOTE-2014 | B26: MWMOTE | C26: 2014 | D26: W2087240369 | E26: 10.1109/tkde.2012.232 | F26: 1153 | G26: =IF(F26="","",ROUND(F26/(2026-C26+1),1)) -> 88.7 | H26: close | I26: yes | J26: Same paper (IEEE TKDE DOI tkde.2012.232); OpenAlex year 2012 is the early-access date, print issue is TKDE 26(2), 2014, so the year differs by 2 from input.
A27: RACOG-2015 | B27: RACOG | C27: 2015 | D27: W2076272581 | E27: 10.1109/tkde.2014.2324567 | F27: 124 | G27: =IF(F27="","",ROUND(F27/(2026-C27+1),1)) -> 10.3 | H27: exact | I27: yes | J27: Full-title and fallback searches were refused (HTTP 429); found via filter=title.search:wRACOG. OpenAlex year 2014 (online-first) vs input 2015. Alt is the ICDM 2013 precursor (different title, DOI 10.1109/icdm.2013.18), listed for reference only. Re-verified 2026-10-18 via batch filter=openalex:...
A28: RBBoost-2015 | B28: Random Balance | C28: 2015 | D28: W769353746 | E28: 10.1016/j.knosys.2015.04.022 | F28: 235 | G28: =IF(F28="","",ROUND(F28/(2026-C28+1),1)) -> 19.6 | H28: exact | I28: yes | J28: Re-verified by batch filter=openalex call on 2026-10-18: count unchanged.
A29: SCUT-2015 | B29: SCUT | C29: 2015 | D29: W2294246171 | E29: 10.5220/0005595502260234 | F29: 105 | G29: =IF(F29="","",ROUND(F29/(2026-C29+1),1)) -> 8.8 | H29: exact | I29: yes | J29: SCITEPRESS DOI (KDIR 2015); input venue was null. Re-verified 2026-10-18 via batch filter=openalex:...; count unchanged.
A30: SMOTE-IPF-2015 | B30: SMOTE-IPF | C30: 2015 | D30: W2107138773 | E30: 10.1016/j.ins.2014.08.051 | F30: 627 | G30: =IF(F30="","",ROUND(F30/(2026-C30+1),1)) -> 52.3 | H30: exact | I30: yes | J30: OpenAlex year 2014 (online first); Information Sciences 291 (2015). A separate precursor paper (IDEAL 2014, 'Managing Borderline and Noisy Examples ... SMOTE with Ensemble Filtering', W10885063, 25 cites) is a different work, not listed as a version.
A31: SplitBal-2015 | B31: SplitBal | C31: 2015 | D31: W2091007025 | E31: 10.1016/j.patcog.2014.11.014 | F31: 414 | G31: =IF(F31="","",ROUND(F31/(2026-C31+1),1)) -> 34.5 | H31: exact | I31: yes | J31: OpenAlex year 2014 (online-first) vs input 2015; Pattern Recognition DOI. Re-verified 2026-10-18 via batch filter=openalex:...; count unchanged.
A32: A-SUWO-2016 | B32: A-SUWO | C32: 2016 | D32: W2172165257 | F32: 291 | G32: =IF(F32="","",ROUND(F32/(2026-C32+1),1)) -> 26.5 | H32: exact | I32: yes | J32: The PDF in the corpus is the dissertation chapter (0 citations in OpenAlex); the method is cited through its Expert Systems with Applications article, which is used.
A33: CGMOS-2016 | B33: CGMOS | C33: 2016 | D33: W2476542064 | E33: 10.1145/2983323.2983789 | F33: 25 | G33: =IF(F33="","",ROUND(F33/(2026-C33+1),1)) -> 2.3 | H33: close | I33: yes | J33: CIKM 2016 version chosen (ACM DOI); OpenAlex display_name is truncated to 'CGMOS'. arXiv 1607.06525 preprint listed as alt. Re-verified 2026-10-18 via batch filter=openalex:...; count unchanged.
A34: MDO-2016 | B34: MDO | C34: 2016 | D34: W2185967890 | E34: 10.1109/tkde.2015.2458858 | F34: 411 | G34: =IF(F34="","",ROUND(F34/(2026-C34+1),1)) -> 37.4 | H34: exact | I34: yes | J34: OpenAlex year 2015 (early access); IEEE TKDE 28(1), 2016. A different 2014 paper by the same authors (Soft Computing, '...over-sampling and boosting techniques', W2027347092, 45 cites) is not a version.
A35: SMOM-2017 | B35: SMOM | C35: 2017 | D35: W2736435690 | E35: 10.1016/j.patcog.2017.07.024 | F35: 277 | G35: =IF(F35="","",ROUND(F35/(2026-C35+1),1)) -> 27.7 | H35: exact | I35: yes | J35: Full-title search was refused (HTTP 429) and the fallback search missed it; found via filter=title.search:multiclass imbalance problems, year 2017 (only 1 hit). Re-verified 2026-10-18 via batch filter=openalex:...; count unchanged.
A36: AMDO-2018 | B36: AMDO | C36: 2018 | D36: W2763110968 | E36: 10.1109/tkde.2017.2761347 | F36: 80 | G36: =IF(F36="","",ROUND(F36/(2026-C36+1),1)) -> 8.9 | H36: exact | I36: yes | J36: OpenAlex year 2017 (early access), issue 2018. Re-verified by batch filter=openalex call on 2026-10-18: count unchanged.
A37: KMeansSMOTE-2018 | B37: k-means SMOTE | C37: 2018 | D37: W2766296277 | E37: 10.1016/j.ins.2018.06.056 | F37: 1273 | G37: =IF(F37="","",ROUND(F37/(2026-C37+1),1)) -> 141.4 | H37: exact | I37: yes | J37: The 2017 arXiv preprint has a different title and was not looked up. Re-verified 2026-10-18 via batch filter=openalex:...; count unchanged.
A38: OBU-2018 | B38: OBU | C38: 2018 | D38: W2900321945 | E38: 10.1007/978-3-030-03493-1_72 | F38: 71 | G38: =IF(F38="","",ROUND(F38/(2026-C38+1),1)) -> 7.9 | H38: exact | I38: yes | J38: Re-verified by batch filter=openalex call on 2026-10-18: count unchanged.
A39: ROS-Buda-2018 | B39: Buda et al. | C39: 2018 | D39: W2767106145 | E39: 10.1016/j.neunet.2018.07.011 | F39: 3053 | G39: =IF(F39="","",ROUND(F39/(2026-C39+1),1)) -> 339.2 | H39: exact | I39: yes | J39: No separate arXiv version appeared in the top search results. Re-verified by batch filter=openalex call on 2026-10-18: count unchanged.
A40: CTGAN-2019 | B40: CTGAN | C40: 2019 | D40: W2954395498 | E40: 10.48550/arxiv.1907.00503 | F40: 982 | G40: =IF(F40="","",ROUND(F40/(2026-C40+1),1)) -> 122.8 | H40: close | I40: yes | J40: Only the arXiv preprint record exists in OpenAlex; no separate NeurIPS 2019 proceedings record was found (also checked with filter=title.search, years 2019-2020). Count likely understates citations to the NeurIPS version. Re-verified 2026-10-18 via batch filter=openalex:...; count unchanged.
...

Sheet summary
A1: status | B1: rows
A2: verified | B2: =COUNTIF(codes!I:I,A2) -> 0
A3: corrected | B3: =COUNTIF(codes!I:I,A3) -> 0
A4: wrong | B4: =COUNTIF(codes!I:I,A4) -> 0
A5: not yet checked | B5: =COUNTA(codes!A:A)-1-SUM(B2:B4) -> 532
A6: total rows | B6: =COUNTA(codes!A:A)-1 -> 532
